Workbook

Sheet Valuation Summary
A1: Eli Lilly Valuation
A2: Valuation Date | B2: 45747
A4: Multiples Valuation | D4: Free Cash Flow Valuation | G4: Market Conditions at Valuation Date
B6: Price Per | E6: Price Per
B7: Share | E7: Share | G7: Price Per Share | I7: 825.91
A8: LTM EBITDA | B8: ='Multiples Valuation'!I42 -> 143.59047 | D8: Base Case | E8: ='Free Cash Flow Valuation'!G52 -> 828.44993
A9: NTM EBITDA | B9: ='Multiples Valuation'!J42 -> 201.33899 | D9: Higher Growth by 0.5% | E9: ='Free Cash Flow Valuation'!R50 -> 1002.3837 | G9: Conclusion
A10: NTM EPS | B10: ='Multiples Valuation'!I32 -> 204.60999 | D10: Lower Growth by 0.5% | E10: ='Free Cash Flow Valuation'!P50 -> 709.11312
D11: Higher WACC by 0.5% | E11: ='Free Cash Flow Valuation'!Q51 -> 693.64483 | G11: Significantly Undervalued
A12: Low | B12: =MIN($B$8:$B$10) -> 143.59047 | D12: Lower WACC by 0.5% | E12: ='Free Cash Flow Valuation'!Q49 -> 1024.8969 | G12: Slightly Undervalued
A13: High | B13: =MAX($B$8:$B$10) -> 204.60999 | G13: Fairly Priced | I13: X | J13: Based on FCF valuation
A14: Mean | B14: =AVERAGE($B$8:$B$10) -> 183.17982 | D14: Low | E14: =MIN($E$8:$E$12) -> 693.64483 | G14: Slightly Overvalued
A15: Median | B15: =MEDIAN($B$8:$B$10) -> 201.33899 | D15: High | E15: =MAX($E$8:$E$12) -> 1024.8969 | G15: Significantly Overvalued | I15: X | J15: Based on comparable multiples
D16: Mean | E16: =AVERAGE($E$8:$E$12) -> 851.6977
D17: Median | E17: =MEDIAN($E$8:$E$12) -> 828.44993

Sheet Multiples Valuation
A1: Multiples Valuation | P1: Eli Lilly and Company (NYSE:LLY) | S1: LLY
P2: 825.91
A3: 1. Comparable Firm Values (exclude your target firm) | P3: {=INDIRECT("'"&S1&"'!C9")} -> 898
C4: @3/31/2025 | E4: [C] * [D] | H4: [F]-[G] | I4: [E]+[H]
C5: Price Per | D5: Shares | E5: Market | F5: Total | G5: Cash and | H5: Net | I5: Enterprise
A6: Firm | B6: Ticker | C6: Share | D6: Out | E6: Cap | F6: Debt | G6: ST Invest | H6: Debt | I6: Value
A7: Johnson & Johnson (NYSE:JNJ) | B7: JNJ | C7: 165.84 | D7: {=INDIRECT("'"&B7&"'!C9")} -> 2409.8 | E7: =C7*D7 -> 399641.23 | F7: =VLOOKUP($A7,Screening!$A$8:$S$149,15,FALSE) -> 37834 | G7: =VLOOKUP($A7,Screening!$A$8:$S$149,14,FALSE) -> 24522 | H7: =F7-G7 -> 13312 | I7: =E7+H7 -> 412953.23
A8: Merck & Co., Inc. (NYSE:MRK) | B8: MRK | C8: 89.76 | D8: {=INDIRECT("'"&B8&"'!C9")} -> 2516.4 | E8: =C8*D8 -> 225872.06 | F8: =VLOOKUP($A8,Screening!$A$8:$S$149,15,FALSE) -> 38270 | G8: =VLOOKUP($A8,Screening!$A$8:$S$149,14,FALSE) -> 13689 | H8: =F8-G8 -> 24581 | I8: =E8+H8 -> 250453.06
A9: Pfizer Inc. (NYSE:PFE) | B9: PFE | C9: 25.34 | D9: {=INDIRECT("'"&B9&"'!C9")} -> 5671.5 | E9: =C9*D9 -> 143715.81 | F9: =VLOOKUP($A9,Screening!$A$8:$S$149,15,FALSE) -> 67418 | G9: =VLOOKUP($A9,Screening!$A$8:$S$149,14,FALSE) -> 20477 | H9: =F9-G9 -> 46941 | I9: =E9+H9 -> 190656.81
A10: Bristol-Myers Squibb Company (NYSE:BMY) | B10: BMY | C10: 60.99 | D10: {=INDIRECT("'"&B10&"'!C9")} -> 2034.8 | E10: =C10*D10 -> 124102.45 | F10: =VLOOKUP($A10,Screening!$A$8:$S$149,15,FALSE) -> 51257 | G10: =VLOOKUP($A10,Screening!$A$8:$S$149,14,FALSE) -> 10859 | H10: =F10-G10 -> 40398 | I10: =E10+H10 -> 164500.45
A11: Zoetis Inc. (NYSE:ZTS) | B11: ZTS | C11: 164.65 | D11: 448.47307 | E11: =C11*D11 -> 73841.091 | F11: =VLOOKUP($A11,Screening!$A$8:$S$149,15,FALSE) -> 6829 | G11: =VLOOKUP($A11,Screening!$A$8:$S$149,14,FALSE) -> 1987 | H11: =F11-G11 -> 4842 | I11: =E11+H11 -> 78683.091
A12: Viatris Inc. (NasdaqGS:VTRS) | B12: VTRS | C12: 8.71 | D12: {=INDIRECT("'"&B12&"'!C9")} -> 1193.7 | E12: =C12*D12 -> 10397.127 | F12: =VLOOKUP($A12,Screening!$A$8:$S$149,15,FALSE) -> 14305.9 | G12: =VLOOKUP($A12,Screening!$A$8:$S$149,14,FALSE) -> 1089.9 | H12: =F12-G12 -> 13216 | I12: =E12+H12 -> 23613.127
A13: Organon & Co. (NYSE:OGN) | B13: OGN | C13: 14.89 | D13: {=INDIRECT("'"&B13&"'!C9")} -> 258 | E13: =C13*D13 -> 3841.62 | F13: =VLOOKUP($A13,Screening!$A$8:$S$149,15,FALSE) -> 9036 | G13: =VLOOKUP($A13,Screening!$A$8:$S$149,14,FALSE) -> 675 | H13: =F13-G13 -> 8361 | I13: =E13+H13 -> 12202.62
A14: Jazz Pharmaceuticals plc (NasdaqGS:JAZZ) | B14: JAZZ | C14: 124.15 | D14: 60.631 | E14: =C14*D14 -> 7527.3387 | F14: =VLOOKUP($A14,Screening!$A$8:$S$149,15,FALSE) -> 6166.9 | G14: =VLOOKUP($A14,Screening!$A$8:$S$149,14,FALSE) -> 2993.8 | H14: =F14-G14 -> 3173.1 | I14: =E14+H14 -> 10700.439
A17: 2. Trailing and Forward Metrics (exclude your target firm)
C18: LTM | D18: NTM | E18: NTM
A19: Firm | B19: Ticker | C19: EBITDA | D19: EBITDA | E19: EPS
A20: =A7 -> Johnson & Johnson (NYSE:JNJ) | B20: =B7 -> JNJ | C20: =VLOOKUP($A20,Screening!$A$8:$S$149,5,FALSE) -> 29940 | D20: =VLOOKUP($A20,Screening!$A$8:$S$149,10,FALSE) -> 33182.8 | E20: =VLOOKUP($A20,Screening!$A$8:$S$149,13,FALSE) -> 10.6
A21: =A8 -> Merck & Co., Inc. (NYSE:MRK) | B21: =B8 -> MRK | C21: =VLOOKUP($A21,Screening!$A$8:$S$149,5,FALSE) -> 29134 | D21: =VLOOKUP($A21,Screening!$A$8:$S$149,10,FALSE) -> 30606.3 | E21: =VLOOKUP($A21,Screening!$A$8:$S$149,13,FALSE) -> 8.98
A22: =A9 -> Pfizer Inc. (NYSE:PFE) | B22: =B9 -> PFE | C22: =VLOOKUP($A22,Screening!$A$8:$S$149,5,FALSE) -> 23322 | D22: =VLOOKUP($A22,Screening!$A$8:$S$149,10,FALSE) -> 26638.8 | E22: =VLOOKUP($A22,Screening!$A$8:$S$149,13,FALSE) -> 2.95
A23: =A10 -> Bristol-Myers Squibb Company (NYSE:BMY) | B23: =B10 -> BMY | C23: =VLOOKUP($A23,Screening!$A$8:$S$149,5,FALSE) -> 19407 | D23: =VLOOKUP($A23,Screening!$A$8:$S$149,10,FALSE) -> 17661.4 | E23: =VLOOKUP($A23,Screening!$A$8:$S$149,13,FALSE) -> 6.74
A24: =A11 -> Zoetis Inc. (NYSE:ZTS) | B24: =B11 -> ZTS | C24: =VLOOKUP($A24,Screening!$A$8:$S$149,5,FALSE) -> 3829 | D24: =VLOOKUP($A24,Screening!$A$8:$S$149,10,FALSE) -> 4194.1 | E24: =VLOOKUP($A24,Screening!$A$8:$S$149,13,FALSE) -> 6.07
A25: =A12 -> Viatris Inc. (NasdaqGS:VTRS) | B25: =B12 -> VTRS | C25: =VLOOKUP($A25,Screening!$A$8:$S$149,5,FALSE) -> 4483.2 | D25: =VLOOKUP($A25,Screening!$A$8:$S$149,10,FALSE) -> 4019.4 | E25: =VLOOKUP($A25,Screening!$A$8:$S$149,13,FALSE) -> 2.2
A26: =A13 -> Organon & Co. (NYSE:OGN) | B26: =B13 -> OGN | C26: =VLOOKUP($A26,Screening!$A$8:$S$149,5,FALSE) -> 1765 | D26: =VLOOKUP($A26,Screening!$A$8:$S$149,10,FALSE) -> 1965.1 | E26: =VLOOKUP($A26,Screening!$A$8:$S$149,13,FALSE) -> 3.85
A27: =A14 -> Jazz Pharmaceuticals plc (NasdaqGS:JAZZ) | B27: =B14 -> JAZZ | C27: =VLOOKUP($A27,Screening!$A$8:$S$149,5,FALSE) -> 1521.7 | D27: =VLOOKUP($A27,Screening!$A$8:$S$149,10,FALSE) -> 1970.5 | E27: =VLOOKUP($A27,Screening!$A$8:$S$149,13,FALSE) -> 23.4 | G27: 4. Target Firm Valuation
I28: NTM
A29: 3. Trailing and Forward Multiples (leave negative multiples blank) | I29: EPS
C30: Ent Val / | D30: Ent Val / | E30: Share Price / | G30: Earnings-Per-Share | I30: =VLOOKUP(P1,Screening!$A$8:$S$149,13,FALSE) -> 23.2
C31: LTM | D31: NTM | E31: NTM | G31: Multpile from Comps | I31: =E42 -> 8.819396
A32: Firm | B32: Ticker | C32: EBITDA | D32: EBITDA | E32: EPS | G32: Estimated Price per Share | I32: =I30*I31 -> 204.60999
A33: =A7 -> Johnson & Johnson (NYSE:JNJ) | B33: =B7 -> JNJ | C33: =$I7/C20 -> 13.792693 | D33: =$I7/D20 -> 12.444798 | E33: =$C7/E20 -> 15.645283
A34: =A8 -> Merck & Co., Inc. (NYSE:MRK) | B34: =B8 -> MRK | C34: =$I8/C21 -> 8.5965904 | D34: =$I8/D21 -> 8.1830559 | E34: =$C8/E21 -> 9.9955457 | I34: LTM | J34: NTM
A35: =A9 -> Pfizer Inc. (NYSE:PFE) | B35: =B9 -> PFE | C35: =$I9/C22 -> 8.1749768 | D35: =$I9/D22 -> 7.1571096 | E35: =$C9/E22 -> 8.5898305 | I35: EBITDA | J35: EBITDA
A36: =A10 -> Bristol-Myers Squibb Company (NYSE:BMY) | B36: =B10 -> BMY | C36: =$I10/C23 -> 8.4763463 | D36: =$I10/D23 -> 9.314123 | E36: =$C10/E23 -> 9.0489614 | G36: EBITDA | I36: =VLOOKUP($P1,Screening!$A$8:$S$149,5,FALSE) -> 19268.3 | J36: =VLOOKUP($P1,Screening!$A$8:$S$149,10,FALSE) -> 27676.3
A37: =A11 -> Zoetis Inc. (NYSE:ZTS) | B37: =B11 -> ZTS | C37: =$I11/C24 -> 20.549253 | D37: =$I11/D24 -> 18.760423 | E37: =$C11/E24 -> 27.125206 | G37: Multpile from Comps | I37: =C42 -> 8.3256616 | J37: =D42 -> 7.6700827
A38: =A12 -> Viatris Inc. (NasdaqGS:VTRS) | B38: =B12 -> VTRS | C38: =$I12/C25 -> 5.2670251 | D38: =$I12/D25 -> 5.874789 | E38: =$C12/E25 -> 3.9590909 | G38: Estimated Enterprise Value | I38: =I36*I37 -> 160421.34 | J38: =J36*J37 -> 212279.51
A39: =A13 -> Organon & Co. (NYSE:OGN) | B39: =B13 -> OGN | C39: =$I13/C26 -> 6.9136657 | D39: =$I13/D26 -> 6.2096687 | E39: =$C13/E26 -> 3.8675325 | G39: Net Debt | I39: =VLOOKUP($P1,Screening!$A$8:$S$149,15,FALSE)-VLOOKUP($P1,Screening!$A$8:$S$149,14,FALSE) -> 31477.1 | J39: =VLOOKUP($P1,Screening!$A$8:$S$149,15,FALSE)-VLOOKUP($P1,Screening!$A$8:$S$149,14,FALSE) -> 31477.1
A40: =A14 -> Jazz Pharmaceuticals plc (NasdaqGS:JAZZ) | B40: =B14 -> JAZZ | C40: =$I14/C27 -> 7.0318976 | D40: =$I14/D27 -> 5.4303165 | E40: =$C14/E27 -> 5.3055556 | G40: Total Equity (Market Cap) | I40: =I38-I39 -> 128944.24 | J40: =J38-J39 -> 180802.41
G41: Shares Outstanding | I41: =LLY!$C$9 -> 898 | J41: =LLY!$C$9 -> 898
A42: Median | C42: =MEDIAN(C33:C40) -> 8.3256616 | D42: =MEDIAN(D33:D40) -> 7.6700827 | E42: =MEDIAN(E33:E40) -> 8.819396 | G42: Estimated Price Per share | I42: =I40/I41 -> 143.59047 | J42: =J40/J41 -> 201.33899

Sheet CAPM and WACC
A1: CAPM and WACC
A3: 1. Unlevering Betas
D4: From | E4: From
D5: Multiples | E5: Multiples | F5: [D]/[E]
H6: Unlevered
A7: Firm | B7: Ticker | C7: Beta (5Y) | D7: Net Debt | E7: Mkt Cap | F7: D/E | G7: Tax Rate | H7: Beta
A8: ='Multiples Valuation'!A7 -> Johnson & Johnson (NYSE:JNJ) | B8: ='Multiples Valuation'!B7 -> JNJ | C8: =HLOOKUP(B8,'Excess Returns and Beta'!$AB$64:$EN$126,63,FALSE) -> 0.4764287 | D8: ='Multiples Valuation'!H7 -> 13312 | E8: ='Multiples Valuation'!E7 -> 399641.23 | F8: =D8/E8 -> 0.033309876 | G8: {=INDIRECT("'"&B8&"'!D5")} -> 0.1664 | H8: =C8/(1+F8*(1-G8)) -> 0.46355706
A9: ='Multiples Valuation'!A8 -> Merck & Co., Inc. (NYSE:MRK) | B9: ='Multiples Valuation'!B8 -> MRK | C9: =HLOOKUP(B9,'Excess Returns and Beta'!$AB$64:$EN$126,63,FALSE) -> 0.35092769 | D9: ='Multiples Valuation'!H8 -> 24581 | E9: ='Multiples Valuation'!E8 -> 225872.06 | F9: =D9/E9 -> 0.10882709 | G9: {=INDIRECT("'"&B9&"'!D5")} -> 0.1667 | H9: =C9/(1+F9*(1-G9)) -> 0.32174963
A10: ='Multiples Valuation'!A9 -> Pfizer Inc. (NYSE:PFE) | B10: ='Multiples Valuation'!B9 -> PFE | C10: =HLOOKUP(B10,'Excess Returns and Beta'!$AB$64:$EN$126,63,FALSE) -> 0.63078468 | D10: ='Multiples Valuation'!H9 -> 46941 | E10: ='Multiples Valuation'!E9 -> 143715.81 | F10: =D10/E10 -> 0.32662377 | G10: {=INDIRECT("'"&B10&"'!D5")} -> 0.1482 | H10: =C10/(1+F10*(1-G10)) -> 0.49348751
A11: ='Multiples Valuation'!A10 -> Bristol-Myers Squibb Company (NYSE:BMY) | B11: ='Multiples Valuation'!B10 -> BMY | C11: =HLOOKUP(B11,'Excess Returns and Beta'!$AB$64:$EN$126,63,FALSE) -> 0.44306942 | D11: ='Multiples Valuation'!H10 -> 40398 | E11: ='Multiples Valuation'!E10 -> 124102.45 | F11: =D11/E11 -> 0.32552137 | G11: {=INDIRECT("'"&B11&"'!D5")} -> 0.1801 | H11: =C11/(1+F11*(1-G11)) -> 0.34972861
A12: ='Multiples Valuation'!A11 -> Zoetis Inc. (NYSE:ZTS) | B12: ='Multiples Valuation'!B11 -> ZTS | C12: =HLOOKUP(B12,'Excess Returns and Beta'!$AB$64:$EN$126,63,FALSE) -> 0.94650828 | D12: ='Multiples Valuation'!H11 -> 4842 | E12: ='Multiples Valuation'!E11 -> 73841.091 | F12: =D12/E12 -> 0.065573246 | G12: 0.209 | H12: =C12/(1+F12*(1-G12)) -> 0.89983523
A13: ='Multiples Valuation'!A12 -> Viatris Inc. (NasdaqGS:VTRS) | B13: ='Multiples Valuation'!B12 -> VTRS | C13: =HLOOKUP(B13,'Excess Returns and Beta'!$AB$64:$EN$126,63,FALSE) -> 0.81254761 | D13: ='Multiples Valuation'!H12 -> 13216 | E13: ='Multiples Valuation'!E12 -> 10397.127 | F13: =D13/E13 -> 1.2711204 | G13: {=INDIRECT("'"&B13&"'!D5")} -> 0.175 | H13: =C13/(1+F13*(1-G13)) -> 0.39662118
A14: ='Multiples Valuation'!A13 -> Organon & Co. (NYSE:OGN) | B14: ='Multiples Valuation'!B13 -> OGN | C14: =HLOOKUP(B14,'Excess Returns and Beta'!$AB$64:$EN$126,63,FALSE) -> 0.77500293 | D14: ='Multiples Valuation'!H13 -> 8361 | E14: ='Multiples Valuation'!E13 -> 3841.62 | F14: =D14/E14 -> 2.1764256 | G14: {=INDIRECT("'"&B14&"'!D5")} -> 0.2288 | H14: =C14/(1+F14*(1-G14)) -> 0.28934653
A15: ='Multiples Valuation'!A14 -> Jazz Pharmaceuticals plc (NasdaqGS:JAZZ) | B15: ='Multiples Valuation'!B14 -> JAZZ | C15: =HLOOKUP(B15,'Excess Returns and Beta'!$AB$64:$EN$126,63,FALSE) -> 0.44494593 | D15: ='Multiples Valuation'!H14 -> 3173.1 | E15: ='Multiples Valuation'!E14 -> 7527.3387 | F15: =D15/E15 -> 0.42154341 | G15: 0.148 | H15: =C15/(1+F15*(1-G15)) -> 0.32736953
A16: Average | H16: =AVERAGE(H8:H15) -> 0.44271191
A18: 2. Relevering Beta
A19: Comparable Unlevered Beta | B19: =AVERAGE(H8:H15) -> 0.44271191 | C19: average of comparable unlevered betas
A20: Net Debt | B20: ='Multiples Valuation'!I39 -> 31477.1
A21: Market Capitalization | B21: ='Multiples Valuation'!P2*'Multiples Valuation'!P3 -> 741667.18
A22: D/E Ratio | B22: =B20/B21 -> 0.042441004
A23: Tax Rate | B23: {=INDIRECT("'"&'Multiples Valuation'!S1&"'!D5")} -> 0.1603
A24: Estimated Levered Equity Beta | B24: =B19*(1+B22*(1-B23)) -> 0.45848915
A26: 3. CAPM
A27: Risk-Free Rate (10-year Treasury) | B27: 0.04245 | C27: from Federal Reserve Statistical Release (as of valuation date). Assume this is an APR with k=2
A28: Convert to EAR | B28: =(1+B27/2)^2-1 -> 0.042900501
A29: Market Risk Premium | B29: 0.05 | C29: Assumption, typically thought to be between 4% and 6%
A30: Expected Return on Equity | B30: =B28+B24*B29 -> 0.065824958
A32: 4. WACC
A33: Credit Rating | B33: Aa3/A+
A34: Expected Return on Debt | B34: 0.0501 | C34: ICE BofA Single-A US Corporate Index Effective Yield on 3/31
A35: Tax Rate | B35: =B23 -> 0.1603
A37: Expected Return on Equity | B37: =B30 -> 0.065824958 | C37: from CAPM
A39: Net Debt | B39: ='Multiples Valuation'!I39 -> 31477.1 | C39: from Multiples
A40: Market Capitalization | B40: =B21 -> 741667.18 | C40: shares times price per share (or just look it up on the comp search sheet)
A41: Enterprise Value | B41: =B40+B39 -> 773144.28 | C41: Net Debt + Market Capitalization
A43: Net Debt-to-Enterprise Value | B43: =B39/B41 -> 0.0407131
A44: Equity-to-Enterprise Value | B44: =B40/B41 -> 0.9592869
A46: WACC | B46: =B43*B34*(1-B35)+B44*B37 -> 0.064857778

Sheet Free Cash Flow Valuation
A1: FCF Valuation
A3: Key Inputs | N3: Notes | Z3: Data table increments
A4: Long-Term Growth Rate | G4: =L33+Z4 -> 0.038 | Z4: 0
A5: WACC | G5: ='CAPM and WACC'!B46+Z5 -> 0.064857778 | Z5: 0
B7: Historical | G7: Provided | J7: Our projections
B8: 2020A | C8: 2021A | D8: 2022A | E8: 2023A | F8: 2024A | G8: 2025E | H8: 2026E | I8: 2027E | J8: 2028E | K8: 2029E | L8: Terminal
A9: Revenue | B9: 24540 | C9: 28318 | D9: 28541 | E9: 34124 | F9: =VLOOKUP('Multiples Valuation'!$P$1,Screening!$A$8:$S$149,4,FALSE) -> 45042.7 | G9: =LLY!D2 -> 59413.32 | H9: =LLY!E2 -> 71106.58 | I9: =LLY!F2 -> 82961.51 | J9: =I9*(1+J10) -> 86114.047 | K9: =J9*(1+K10) -> 89386.381 | L9: =K9*(1+L10) -> 92783.064
A10: Growth | B10: =B9/22320-1 -> 0.099462366 | C10: =C9/B9-1 -> 0.15395273 | D10: =D9/C9-1 -> 0.0078748499 | E10: =E9/D9-1 -> 0.19561333 | F10: =F9/E9-1 -> 0.31997128 | G10: =G9/F9-1 -> 0.31904437 | H10: =H9/G9-1 -> 0.1968121 | I10: =I9/H9-1 -> 0.16672058 | J10: 0.038 | K10: 0.038 | L10: 0.038
A12: EBITDA | B12: =B15+B26 -> 8955.84 | C12: =C15+C26 -> 10014.682 | D12: =D15+D26 -> 10370.21 | E12: =E15+E26 -> 12359.3 | F12: =VLOOKUP('Multiples Valuation'!$P$1,Screening!$A$8:$S$149,5,FALSE) -> 19268.3 | G12: =LLY!D3 -> 27690.85 | H12: =LLY!E3 -> 34459.71 | I12: =LLY!F3 -> 41098.96 | J12: =J13*J9 -> 35306.759 | K12: =K13*K9 -> 36648.416 | L12: =L13*L9 -> 38041.056 | N12: 25 - '27 significant positive impact of Mounjaro, Zepbound, and incretins
A13: as % of Revenue | B13: =B12/B9 -> 0.36494866 | C13: =C12/C9 -> 0.35365075 | D13: =D12/D9 -> 0.36334431 | E13: =E12/E9 -> 0.3621879 | F13: =F12/F9 -> 0.42777853 | G13: =G12/G9 -> 0.46607141 | H13: =H12/H9 -> 0.48462055 | I13: =I12/I9 -> 0.49539793 | J13: 0.41 | K13: 0.41 | L13: 0.41 | N13: Tapered terminal margin down to '20 - '27 average
A15: EBIT | B15: 7631.94 | C15: 8467.082 | D15: 8847.71 | E15: 10832 | F15: =VLOOKUP('Multiples Valuation'!$P$1,Screening!$A$8:$S$149,6,FALSE) -> 17501.7 | G15: =LLY!D3-LLY!D4 -> 25918.98 | H15: =LLY!E3-LLY!E4 -> 32457 | I15: =LLY!F3-LLY!F4 -> 38721.6 | J15: =J16*J9 -> 31862.198 | K15: =K16*K9 -> 33072.961 | L15: =L16*L9 -> 34329.734 | N15: 25 - '27 significant positive impact of Mounjaro, Zepbound, and incretins
A16: as % of Revenue | B16: =B15/B9 -> 0.311 | C16: =C15/C9 -> 0.299 | D16: =D15/D9 -> 0.31 | E16: =E15/E9 -> 0.31743055 | F16: =F15/F9 -> 0.38855797 | G16: =G15/G9 -> 0.43624864 | H16: =H15/H9 -> 0.45645565 | I16: =I15/I9 -> 0.46674175 | J16: 0.37 | K16: 0.37 | L16: 0.37 | N16: Tapered terminal margin down to '20 - '27 average
A18: Tax Rate | B18: 0.142 | C18: 0.123 | D18: 0.103 | E18: 0.201 | F18: 0.169 | G18: =LLY!D5 -> 0.1603 | H18: =LLY!E5 -> 0.1621 | I18: =LLY!F5 -> 0.1631 | J18: 0.162 | K18: 0.162 | L18: 0.162
A19: Unlevered Income Taxes | G19: =G15*G18 -> 4154.8125 | H19: =H15*H18 -> 5261.2797 | I19: =I15*I18 -> 6315.493 | J19: =J15*J18 -> 5161.676 | K19: =K15*K18 -> 5357.8197 | L19: =L15*L18 -> 5561.4168
A21: After-Tax EBIT | G21: =(1-G18)*G15 -> 21764.168 | H21: =(1-H18)*H15 -> 27195.72 | I21: =(1-I18)*I15 -> 32406.107 | J21: =(1-J18)*J15 -> 26700.522 | K21: =(1-K18)*K15 -> 27715.141 | L21: =(1-L18)*L15 -> 28768.317
A23: Capital Expenditures | B23: 1387.9 | C23: 1309.8 | D23: 1854.3 | E23: 3448 | F23: 5058 | G23: =LLY!D6 -> 5067.81 | H23: =LLY!E6 -> 5235.77 | I23: =LLY!F6 -> 4892.61 | J23: =J9*J24 -> 6889.1238 | K23: =K9*K24 -> 7150.9105 | L23: =L9*L24 -> 7422.6451
A24: as % of Revenue | B24: =B23/B9 -> 0.056556642 | C24: =C23/C9 -> 0.046253266 | D24: =D23/D9 -> 0.064969693 | E24: =E23/E9 -> 0.10104325 | F24: =F23/F9 -> 0.11229345 | G24: =G23/G9 -> 0.085297539 | H24: =H23/H9 -> 0.073632707 | I24: =I23/I9 -> 0.058974457 | J24: 0.08 | K24: 0.08 | L24: 0.08
A26: Depreciation & Amortization | B26: 1323.9 | C26: 1547.6 | D26: 1522.5 | E26: 1527.3 | F26: 1766.6 | G26: =LLY!D4 -> 1771.87 | H26: =LLY!E4 -> 2002.71 | I26: =LLY!F4 -> 2377.36 | J26: =J12-J15 -> 3444.5619 | K26: =K12-K15 -> 3575.4552 | L26: =L12-L15 -> 3711.3225
A27: as % of Capital Expenditures | B27: =B26/B23 -> 0.95388717 | C27: =C26/C23 -> 1.1815544 | D27: =D26/D23 -> 0.82106455 | E27: =E26/E23 -> 0.44295244 | F27: =F26/F23 -> 0.34926849 | G27: =G26/G23 -> 0.34963229 | H27: =H26/H23 -> 0.38250534 | I27: =I26/I23 -> 0.48590834 | ... L27: =L26/L23 -> 0.5
A29: Change in Net Working Capital | G29: =LLY!D7-LLY!C7 -> 1136.9 | H29: =LLY!E7-LLY!D7 -> 1500 | I29: =LLY!F7-LLY!E7 -> 1000 | J29: =J30*(J9-I9) -> 315.25374 | K29: =K30*(K9-J9) -> 327.23338 | L29: =L30*(L9-K9) -> 339.66825
A30: as % of Revenue growth | G30: =G29/(G9-LLY!C2) -> 0.079112801 | H30: =H29/(H9-G9) -> 0.12827903 | I30: =I29/(I9-H9) -> 0.084353092 | J30: 0.1 | K30: 0.1 | L30: 0.1
A32: Unlevered Free Cash Flow | G32: =G21-G23+G26-G29 -> 17331.328 | H32: =H21-H23+H26-H29 -> 22462.66 | I32: =I21-I23+I26-I29 -> 28890.857 | J32: =J21-J23+J26-J29 -> 22940.706 | K32: =K21-K23+K26-K29 -> 23812.453 | L32: =L21-L23+L26-L29 -> 24717.326
A33: Growth | H33: =H32/G32-1 -> 0.29607269 | I33: =I32/H32-1 -> 0.28617255 | J33: =J32/I32-1 -> -0.20595274 | K33: =K32/J32-1 -> 0.038 | L33: =L32/K32-1 -> 0.038
A35: Portion of Year | G35: 0.75 | H35: 1 | I35: 1 | J35: 1 | K35: 1
A36: Time | G36: =G35 -> 0.75 | H36: =G36+1 -> 1.75 | I36: =H36+1 -> 2.75 | J36: =I36+1 -> 3.75 | K36: =J36+1 -> 4.75
A37: PV Factor | G37: =(1+$G$5)^-G36 -> 0.95396248 | H37: =(1+$G$5)^-H36 -> 0.89585905 | I37: =(1+$G$5)^-I36 -> 0.84129456 | J37: =(1+$G$5)^-J36 -> 0.79005345 | K37: =(1+$G$5)^-K36 -> 0.7419333
A39: PV of Free Cash Flow | G39: =G32*G35*G37 -> 12400.077 | H39: =H32*H35*H37 -> 20123.378 | I39: =I32*I35*I37 -> 24305.721 | J39: =J32*J35*J37 -> 18124.384 | K39: =K32*K35*K37 -> 17667.252
A41: First Stage PV | G41: =SUM(G39:K39) -> 92620.811
A43: Second Stage FV at 2029 | G43: =L32/(G5-G4) -> 920304.2 | H43: Implied Terminal Forward EBITDA multiple ----> | N43: second stage value as of 2029 divided by Terminal Year EBITDA
A44: Second Stage PV | G44: =G43*K37 -> 682804.33 | H44: Uses same PV factor as the 2029 FCF
A46: Enterprise Value | G46: =G44+G41 -> 775425.14 | N46: Sensitivity to growth rate and WACC
A47: Excess Cash | G47: =VLOOKUP('Multiples Valuation'!$P$1,Screening!$A$8:$S$149,14,FALSE) -> 3433.5 | P47: Growth rate sensitivity
A48: Firm Value | G48: =G46+G47 -> 778858.64 | O48: =G52 -> 828.44993 | P48: -0.005 | Q48: 0 | R48: 0.005
A49: Total Debt | G49: =VLOOKUP('Multiples Valuation'!$P$1,Screening!$A$8:$S$149,15,FALSE) -> 34910.6 | N49: WACC Sensitivity | O49: -0.005 | P49: 847.03091 | Q49: 1024.8969 | R49: 1308.2727
A50: Total Equity | G50: =G48-G49 -> 743948.04 | O50: 0 | P50: 709.11312 | Q50: 828.44993 | R50: 1002.3837
A51: Shares Outstanding | G51: ='Multiples Valuation'!I41 -> 898 | O51: 0.005 | P51: 608.59924 | Q51: 693.64483 | R51: 810.35558
A52: Price Per Share | G52: =G50/G51 -> 828.44993

Sheet JNJ
C1: 2024 (Historical) | D1: 2025 | E1: 2026 | F1: 2027
A2: Revenue | B2: millions of USD | C2: 88821 | D2: 90259.52 | E2: 94012.03 | F2: 98044.27
A3: EBITDA | B3: millions of USD | D3: 33274.21 | E3: 34681.25 | F3: 37635.96
A4: Depreciation & Amortization | B4: millions of USD | D4: 7548.93 | E4: 7744.91 | F4: 8105.09
A5: Income Tax Rate | B5: percentage | D5: 0.1664 | E5: 0.1675 | F5: 0.1676
A6: Capital Expenditures | B6: millions of USD | D6: 3918.09 | E6: 4071.27 | F6: 4078.21
A7: Level of Net Working Capital | B7: millions of USD | C7: 5572 | D7: 5820 | E7: 6090 | F7: 6200
A9: Shares Outstanding | B9: millions of shares | C9: 2409.8

Sheet MRK
C1: 2024 (Historical) | D1: 2025 | E1: 2026 | F1: 2027
A2: Revenue | B2: millions of USD | C2: 64168 | D2: 65084.56 | E2: 69327.83 | F2: 72952.46
A3: EBITDA | B3: millions of USD | D3: 30535.91 | E3: 33166.32 | F3: 35762.91
A4: Depreciation & Amortization | B4: millions of USD | D4: 3060.47 | E4: 3069.27 | F4: 3073.42
A5: Income Tax Rate | B5: percentage | D5: 0.1667 | E5: 0.1679 | F5: 0.1679
A6: Capital Expenditures | B6: millions of USD | D6: 3277.8 | E6: 3566.17 | F6: 3466.75
A7: Level of Net Working Capital | B7: millions of USD | C7: 10362 | D7: 11000 | E7: 11500 | F7: 12000
A9: Shares Outstanding | B9: millions of shares | C9: 2516.4

Sheet PFE
C1: 2024 (Historical) | D1: 2025 | E1: 2026 | F1: 2027
A2: Revenue | B2: millions of USD | C2: 63627 | D2: 62900.36 | E2: 62889.41 | F2: 61712.85
A3: EBITDA | B3: millions of USD | D3: 26581.67 | E3: 26735.33 | F3: 26148.63
A4: Depreciation & Amortization | B4: millions of USD | D4: 7189.01 | E4: 7028.68 | F4: 6944.95
A5: Income Tax Rate | B5: percentage | D5: 0.1482 | E5: 0.1494 | F5: 0.1494
A6: Capital Expenditures | B6: millions of USD | D6: 2907.74 | E6: 2724.11 | F6: 2625.51
A7: Level of Net Working Capital | B7: millions of USD | C7: 7363 | D7: 7800 | E7: 8200 | F7: 8700
A9: Shares Outstanding | B9: millions of shares | C9: 5671.5

Sheet BMY
C1: 2024 (Historical) | D1: 2025 | E1: 2026 | F1: 2027
A2: Revenue | B2: millions of USD | C2: 48300 | D2: 45803.74 | E2: 43015.2 | F2: 42813.06
A3: EBITDA | B3: millions of USD | D3: 17563.89 | E3: 15383.14 | F3: 15586.14
A4: Depreciation & Amortization | B4: millions of USD | D4: 6162.06 | E4: 5122.49 | F4: 4709.72
A5: Income Tax Rate | B5: percentage | D5: 0.1801 | E5: 0.1751 | F5: 0.1754
A6: Capital Expenditures | B6: millions of USD | D6: 1138.68 | E6: 1104.42 | F6: 1086.14
A7: Level of Net Working Capital | B7: millions of USD | C7: 6006 | D7: 6000 | E7: 6500 | F7: 7000
A9: Shares Outstanding | B9: millions of shares | C9: 2034.8

Sheet VTRS
C1: 2024 (Historical) | D1: 2025 | E1: 2026 | F1: 2027
A2: Revenue | B2: millions of USD | C2: 14739 | D2: 13793.55 | E2: 13958.57 | F2: 14104.99
A3: EBITDA | B3: millions of USD | D3: 4023.64 | E3: 4183.27 | F3: 4401.5
A4: Depreciation & Amortization | B4: millions of USD | D4: 342.02 | E4: 333.12 | F4: 253.16
A5: Income Tax Rate | B5: percentage | D5: 0.175 | E5: 0.1888 | F5: 0.1833
A6: Capital Expenditures | B6: millions of USD | D6: 377.2 | E6: 410.62 | F6: 391.46
A7: Level of Net Working Capital | B7: millions of USD | C7: 3738.4 | D7: 3750 | E7: 3800 | F7: 3850
A9: Shares Outstanding | B9: millions of shares | C9: 1193.7

Sheet OGN
C1: 2024 (Historical) | D1: 2025 | E1: 2026 | F1: 2027
A2: Revenue | B2: millions of USD | C2: 6403 | D2: 6286.58 | E2: 6366.46 | F2: 6341.67
A3: EBITDA | B3: millions of USD | D3: 1967.16 | E3: 2007.33 | F3: 2077.81
A4: Depreciation & Amortization | B4: millions of USD | D4: 187.75 | E4: 196.25 | F4: 222.33
A5: Income Tax Rate | B5: percentage | D5: 0.2288 | E5: 0.235 | F5: 0.2317
A6: Capital Expenditures | B6: millions of USD | D6: 192 | E6: 207 | F6: 185.33
A7: Level of Net Working Capital | B7: millions of USD | C7: 1630 | D7: 1675 | E7: 1725 | F7: 1800
A9: Shares Outstanding | B9: millions of shares | C9: 258

Sheet PRGO
C1: 2024 (Historical) | D1: 2025 | E1: 2026 | F1: 2027
A2: Revenue | B2: millions of USD | C2: 4373.4 | D2: 4436.44 | E2: 4537.89 | F2: 4661.4
A3: EBITDA | B3: millions of USD | D3: 764.92 | E3: 824.87 | F3: 890.36
A4: Depreciation & Amortization | B4: millions of USD | D4: 325.5 | E4: 334.27 | F4: 343.77
A5: Income Tax Rate | B5: percentage | D5: 0.201 | E5: 0.205 | F5: 0.205
A6: Capital Expenditures | B6: millions of USD | D6: 144 | E6: 147 | F6: 149
A7: Level of Net Working Capital | B7: millions of USD | C7: 1437.7 | D7: 1600 | E7: 1700 | F7: 1725
A9: Shares Outstanding | B9: millions of shares | C9: 136.5

Sheet LLY
C1: 2024 (Historical) | D1: 2025 | E1: 2026 | F1: 2027
A2: Revenue | B2: millions of USD | C2: 45042.7 | D2: 59413.32 | E2: 71106.58 | F2: 82961.51
A3: EBITDA | B3: millions of USD | D3: 27690.85 | E3: 34459.71 | F3: 41098.96
A4: Depreciation & Amortization | B4: millions of USD | D4: 1771.87 | E4: 2002.71 | F4: 2377.36
A5: Income Tax Rate | B5: percentage | D5: 0.1603 | E5: 0.1621 | F5: 0.1631
A6: Capital Expenditures | B6: millions of USD | D6: 5067.81 | E6: 5235.77 | F6: 4892.61
A7: Level of Net Working Capital | B7: millions of USD | C7: 4363.1 | D7: 5500 | E7: 7000 | F7: 8000
A9: Shares Outstanding | B9: millions of shares | C9: 898

Sheet Tax Rates
A6: Capital IQ Company Screening Report > Taxes
A8: Company Name | B8: Exchange:Ticker | C8: Effective Tax Rate - Capital IQ [NTM] (%)
A9: Corcept Therapeutics Incorporated (NasdaqCM:CORT) | B9: NasdaqCM:CORT | C9: 17.3
A10: Journey Medical Corporation (NasdaqCM:DERM) | B10: NasdaqCM:DERM | C10: 21
A11: ANI Pharmaceuticals, Inc. (NasdaqGM:ANIP) | B11: NasdaqGM:ANIP | C11: 24.6
A12: Avadel Pharmaceuticals plc (NasdaqGM:AVDL) | B12: NasdaqGM:AVDL | C12: 9.25
A13: biote Corp. (NasdaqGM:BTMD) | B13: NasdaqGM:BTMD | C13: 23.6
A14: CorMedix Inc. (NasdaqGM:CRMD) | B14: NasdaqGM:CRMD | C14: 2
A15: Eton Pharmaceuticals, Inc. (NasdaqGM:ETON) | B15: NasdaqGM:ETON | C15: 10
A16: Harmony Biosciences Holdings, Inc. (NasdaqGM:HRMY) | B16: NasdaqGM:HRMY | C16: 23.7
A17: Harrow, Inc. (NasdaqGM:HROW) | B17: NasdaqGM:HROW | C17: 15
A18: Ligand Pharmaceuticals Incorporated (NasdaqGM:LGND) | B18: NasdaqGM:LGND | C18: 19.6
A19: Supernus Pharmaceuticals, Inc. (NasdaqGM:SUPN) | B19: NasdaqGM:SUPN | C19: 20.5
A20: Amphastar Pharmaceuticals, Inc. (NasdaqGS:AMPH) | B20: NasdaqGS:AMPH | C20: 20.4
... A33: Zoetis Inc. (NYSE:ZTS) | B33: NYSE:ZTS | C33: 20.9

Sheet Decimal Format
A1: YEAR | B1: MONTH | C1: SPY | D1: TBILL | E1: ACRS | F1: ADIL | G1: ALMS | H1: ALTS | I1: AMLX | J1: AMPH | K1: AMRX | L1: ANEB | M1: ANIP | N1: ANRO | O1: ANTX | P1: AQST | Q1: ARTL | R1: ARVN | S1: ASBP | T1: ASRT | U1: ATHA | V1: AVDL | W1: AVIR | X1: AXSM | Y1: AYTU | Z1: BFRI | AA1: BIOA | AB1: BMY | AC1: BTMD | AD1: CALC | AE1: CARA | AF1: CGTX | AG1: CING | AH1: CLSD | AI1: CNSP | AJ1: CNTX | AK1: COCP | AL1: COLL | AM1: CORT | AN1: CPHI | AO1: CPIX | AP1: CRMD | AQ1: CTNM | AR1: CTXR | AS1: CVKD | AT1: DARE | AU1: DERM | AV1: DRRX | AW1: ELAN | AX1: ELVN | AY1: ENVB | AZ1: EOLS | BA1: ESPR | BB1: ETON | BC1: EVOK | BD1: EWTX | BE1: EYEN | BF1: EYPT | BG1: FULC | BH1: GHRS | BI1: GRCE | BJ1: HEPA | BK1: HOTH | BL1: HRMY | BM1: HROW | BN1: IBO | BO1: IGC | BP1: IKNA | BQ1: INVA | BR1: IRD | BS1: ITCI | BT1: ITRM | BU1: IXHL | BV1: JAGX | BW1: JAZZ | BX1: JNJ | BY1: JUNS | BZ1: KPRX | CA1: LEXX | CB1: LGND | CC1: LLY | CD1: LPCN | CE1: LQDA | CF1: LYRA | CG1: MAZE | CH1: MBX | CI1: MIRA | CJ1: MRK | CK1: NBY | CL1: NKTR | CM1: NMRA | CN1: NRXP | CO1: NTRB | CP1: NUVB | CQ1: OCUL | CR1: OGN | CS1: OMER | CT1: OPTN | CU1: ORMP | CV1: PAHC | CW1: PBH | CX1: PCRX | CY1: PCSA | CZ1: PFE | DA1: PHAT | DB1: PLRX | DC1: PRGO | DD1: PRPH | DE1: PTPI | DF1: PULM | DG1: RANI | DH1: RAPP | DI1: RLMD | DJ1: RVPH | DK1: SAVA | DL1: SCLX | DM1: SCPH | DN1: SCYX | DO1: SEPN | DP1: SIGA | DQ1: SNES | DR1: SNOA | DS1: SUPN | DT1: SXTP | DU1: TARS | DV1: TELO | DW1: TERN | DX1: THRD | DY1: TLPH | DZ1: TLRY | EA1: TNFA | EB1: TRAW | EC1: TRVI | ED1: TTNP | EE1: TXMD | EF1: VERU | EG1: VRCA | EH1: VRPX | EI1: VTRS | EJ1: VTYX | EK1: VYNE | EL1: XERS | EM1: YCBD | EN1: ZTS | EO1: ZVRA
A2: 2020 | B2: 3 | C2: -0.12464237 | D2: 0.0020473632 | E2: -0.087719298 | F2: -0.097222222 | H2: -0.36 | J2: -0.035737492 | K2: -0.096103896 | M2: -0.15142679 | P2: -0.41286863 | Q2: -0.10280374 | R2: -0.14491831 | T2: -0.39814815 | V2: -0.20520521 | X2: -0.24576923 | Y2: 1.8301887 | AB2: -0.056215219 | AE2: -0.12109115 | AH2: -0.24107143 | AI2: -0.43548387 | AK2: -0.46616541 | AL2: -0.31242105 | AM2: -0.057844691 | AN2: -0.12280702 | AO2: -0.099255583 | AP2: -0.30961538 | AR2: -0.15730337 | AT2: -0.22018349 | AV2: -0.12429379 | AW2: -0.18284672 | AY2: -0.163034 | AZ2: -0.51688009 | BA2: -0.3755199 | BB2: -0.24074074 | BC2: -0.056910569 | BE2: -0.41025641 | BF2: -0.20930233 | BG2: -0.36892178 | BJ2: -0.50558659 | BK2: -0.27021226 | BM2: -0.30797101 | BO2: 0.11363636 | BQ2: -0.12694878 | BR2: -0.22746781 | BS2: -0.27156398 | BT2: 0.12916667 | BV2: -0.15789474 | BW2: -0.1295165 | BX2: -0.024910801 | BZ2: -0.095652174 | CA2: -0.12121212 | CB2: -0.22307692 | CC2: 0.099818252 | CD2: -0.034205231 | CE2: 0.14043584 | CJ2: 0.012951052 | CK2: 0.052631579 | CL2: -0.14223931 | CN2: 0.011267606 | CO2: 0.50000583 | CQ2: 0.052072264 | CS2: 0.12258606 | CT2: -0.25785124 | CU2: -0.25490196 | CV2: -0.038269983 | CW2: -0.018201285 | CX2: -0.22706316 | CY2: 0.025641026 | CZ2: -0.023339184 | DA2: -0.28516058 | DC2: -0.051291715 | DD2: -0.025728383 | DF2: -0.36875 | DI2: -0.30073801 | DJ2: -0.0037878788 | DK2: -0.26737968 | DM2: -0.16384181 | DN2: -0.1673774 | DP2: -0.04400049 | DQ2: -0.37650602 | DR2: -0.070208729 | DS2: 0 | DY2: -0.10606061 | DZ2: -0.52321552 | EA2: -0.23201439 | EB2: -0.30232558 | EC2: -0.36608863 | ED2: -0.11538462 | EE2: -0.37278107 | EF2: -0.20823245 | EG2: -0.079191238 | EK2: -0.091525424 | EL2: -0.45224719 | EM2: -0.088235294 | EN2: -0.11664052 | EO2: -0.25742574
A3: 2020 | B3: 4 | C3: 0.12698322 | D3: -0.00019324052 | E3: 0.27884615 | F3: 0.13846154 | H3: 0.16517857 | J3: 0.14218329 | K3: 0.043103448 | M3: -0.017918508 | P3: 0.96803653 | Q3: 0.22916667 | R3: 0.30272953 | T3: 0.35384615 | V3: 0.30730479 | X3: 0.61533231 | Y3: 0.093333333 | AB3: 0.099850495 | AE3: 0.12187737 | AH3: 0.16470588 | AI3: 0.36666667 | AK3: 0.32394366 | AL3: 0.26638089 | AM3: 0.064760303 | AN3: -0.04 | AO3: 0.090909091 | AP3: 0.15598886 | AR3: 0.53166667 | AT3: 0.30588235 | AV3: 0.37419355 | AW3: 0.10361769 | AY3: -0.052083333 | AZ3: 0.0024096386 | BA3: 0.25594672 | BB3: 0.26341463 | BC3: 0.14655172 | BE3: 0.59130435 | BF3: -0.049019608 | BG3: 0.056951424 | BJ3: 0.056497175 | BK3: 0.16013072 | BM3: 0.17539267 | BO3: 0.10204082 | BQ3: 0.20578231 | BR3: 0.055555556 | BS3: 0.14964216 | BT3: 0.29151292 | BV3: -0.05 | BW3: 0.10537397 | BX3: 0.14420735 | BZ3: 0.0019230769 | CA3: 0 | CB3: 0.35547305 | CC3: 0.11476347 | CD3: 0.15416667 | CE3: 0.057324841 | CJ3: 0.031192157 | CK3: 0.53333333 | CL3: 0.075630252 | CN3: 0.10027855 | CO3: -0.2 | CQ3: 0.16363636 | CS3: 0.24308153 | CT3: -0.10022272 | CU3: 0.016447368 | CV3: 0.10508994 | CW3: 0.10932388 | CX3: 0.23143454 | CY3: -0.25 | CZ3: 0.1752481 | DA3: 0.31061193 | DC3: 0.10833905 | DD3: -0.11642349 | DF3: 0.36633663 | DI3: 0.23013779 | DJ3: 0.0085551331 | DK3: 0.85766423 | DM3: 0.27567568 | DN3: 0.23559539 | DP3: 0.23641026 | DQ3: 0.038647343 | DR3: 0.036734694 | DS3: 0.30072262 | DY3: 0.36440678 | DZ3: 0.17005814 | EA3: 0.6206089 | EB3: 0.033333333 | EC3: -0.12765957 | ED3: 0.13043478 | EE3: 0.49056604 | EF3: -0.012232416 | EG3: 0.10430009 | EK3: -0.32089552 | EL3: 0.38461538 | EM3: 0.035483871 | EN3: 0.10045752 | EO3: 0.33333333
A4: 2020 | B4: 5 | C4: 0.047645592 | D4: -0.00017111862 | E4: 0.060150376 | F4: 0.094594595 | H4: 0.21072797 | J4: 0.099705015 | K4: 0.3415978 | M4: -0.22369408 | P4: 0.12993039 | Q4: 0.084745763 | R4: -0.36628571 | T4: 0.125 | V4: -0.22157996 | X4: -0.18994002 | Y4: -0.091463415 | AB4: -0.017923128 | AE4: 0.070850202 | AH4: -0.060606061 | AI4: -0.073170732 | AK4: 0.031914894 | AL4: 0.066247582 | AM4: 0.19589258 | AN4: -0.0625 | AO4: -0.16414141 | AP4: 0.065060241 | AR4: -0.055495103 | AT4: -0.054054054 | AV4: 0.098591549 | AW4: -0.13354917 | AX4: 0.91371429 | AY4: 0.45054945 | AZ4: 0.098557692 | BA4: 0.069949495 | BB4: -0.11196911 | BC4: 0.85714286 | BE4: -0.21038251 | BF4: -0.11340206 | BG4: 0.57765452 | BJ4: -0.010695187 | BK4: -0.18591549 | BM4: 0.20489978 | BO4: 0.074074074 | BQ4: -0.014809591 | BR4: 0.32105263 | BS4: 0.18166384 | BT4: 0.20285714 | BV4: 0.059210526 | BW4: 0.082267574 | BX4: -0.0016618646 | BZ4: -0.021113244 | CA4: 0.034482759 | CB4: 0.030435224 | CC4: -0.0063077818 | CD4: 0.64981949 | CE4: 0.85542169 | CJ4: 0.017394236 | CK4: -0.076086957 | CL4: 0.13020833 | CN4: -0.065654008 | CO4: -0.14583738 | CQ4: 0.22222222 | CS4: -0.10469314 | CT4: 0.069306931 | CU4: 0.01618123 | CV4: -0.0190965 | CW4: 0.037109855 | CX4: 0.064422378 | CY4: 0.066666667 | CZ4: 0.0058041867 | DA4: 0.24940898 | DC4: 0.031779238 | DD4: -0.04790174 | DF4: 0.2173913 | DI4: 0.14895138 | DJ4: -0.0065975495 | DK4: -0.71971185 | DM4: -0.11758475 | DN4: -0.21865285 | DP4: 0.013542099 | DQ4: -0.11162791 | DR4: 0.90944882 | DS4: 0.030769231 | DY4: -0.13664596 | DZ4: 0.22360248 | EA4: -0.01734104 | EB4: 0.35483871 | EC4: -0.045296167 | ED4: 0.076923077 | EE4: -0.28481013 | EF4: 0.15479876 | EG4: -0.048881524 | EK4: 0.31318681 | EL4: 0.9037037 | EM4: 0.52647975 | EN4: 0.077952343 | EO4: -0.37333333
A5: 2020 | B5: 6 | C5: 0.017760594 | D5: 0 | E5: 0.14893617 | F5: -0.14197531 | H5: 0.012658228 | J5: 0.20493562 | K5: -0.022587269 | M5: 0.04121056 | P5: -0.0020533881 | Q5: -0.0546875 | R5: 0.0081154193 | T5: -0.13131313 | V5: 0 | X5: 0.068849052 | Y5: -0.046979866 | AB5: -0.015406399 | AE5: 0.077504726 | AH5: 0.010752688 | AI5: -0.19548872 | AK5: 0.56701031 | AL5: -0.20634921 | AM5: 0.11096433 | AN5: 0.48888889 | AO5: 0.0060422961 | AP5: 0.42533937 | AR5: 0.30184332 | AT5: -0.058095238 | AV5: -0.0085470085 | AW5: 0.0018682858 | AX5: -0.17497761 | AY5: 0.17424242 | AZ5: 0.15973742 | BA5: 0.21099835 | BB5: 0.18478261 | BC5: 0.43319838 | BE5: -0.017301038 | BF5: -0.11627907 | BG5: -0.081366148 | BJ5: 0.54594595 | BK5: -0.10726644 | BM5: -0.036968577 | BO5: 0.034482759 | BQ5: 0.00071581961 | BR5: 0.1314741 | BS5: 0.22940613 | BT5: -0.71733967 | BV5: 0.0041407867 | BW5: -0.075259806 | BX5: -0.054587914 | BZ5: -0.056862745 | CA5: -0.015666667 | CB5: 0.10121099 | CC5: 0.073422731 | CD5: 0.3785558 | CE5: -0.088744589 | CJ5: -0.034337446 | CK5: 0.35294118 | CL5: 0.067281106 | CN5: -0.05166185 | CO5: 0 | CQ5: 0.18323864 | CS5: -0.010752688 | CT5: 0.72222222 | CU5: 0.12420382 | CV5: 0.0073585706 | CW5: -0.10995261 | CX5: 0.19385666 | CY5: 0.125 | CZ5: -0.14375603 | DA5: -0.22161779 | DC5: 0.0091291706 | DD5: -0.094316634 | DF5: 0.023809524 | DI5: -0.071769342 | DJ5: 0.019924099 | DK5: 0.43925234 | DM5: -0.11644658 | DN5: -0.0039787798 | DP5: -0.013361161 | DQ5: 0.047120419 | DR5: -0.26597938 | DS5: -0.015339967 | DY5: -0.1294964 | DZ5: -0.27817259 | EA5: 0.023529412 | EB5: 0.35714286 | EC5: 1.4014599 | ED5: 0.10714286 | EE5: 0.10619469 | EF5: -0.10455764 | EG5: -0.040940767 | EK5: -0.27615063 | EL5: -0.48249027 | EM5: 0.29931973 | EN5: -0.016858777 | EO5: 0.52659574
A6: 2020 | B6: 7 | C6: 0.05889233 | D6: 0.00010958391 | E6: 0.32716049 | F6: 0.15827338 | H6: 0.23125 | J6: -0.10863758 | K6: -0.090336134 | M6: -0.084415584 | P6: 0.082304527 | Q6: -0.049586777 | R6: -0.060822898 | T6: 0.047209302 | V6: -0.030940594 | X6: -0.13308216 | Y6: -0.021126761 | AB6: 0.0052111106 | AE6: -0.038596491 | AH6: -0.12765957 | AI6: -0.13084112 | AK6: 0.11184211 | AL6: -0.098285714 | AM6: -0.11117717 | AN6: -0.28358209 | AO6: 0 | AP6: -0.29365079 | AR6: 0.14159292 | AT6: 0.1223458 | AV6: -0.15517241 | AW6: 0.1016317 | AX6: -0.26927253 | AY6: 0.19354839 | AZ6: -0.38490566 | BA6: -0.26661469 | BB6: 0.22568807 | BC6: 0.042372881 | BE6: 0.23943662 | BF6: -0.065789474 | BG6: -0.13231274 | BJ6: 0.41258741 | BK6: 0.058139535 | BM6: 0.051823417 | BO6: 0.016666667 | BQ6: -0.03111588 | BR6: -0.063380282 | BS6: -0.2276977 | BT6: -0.12605042 | BV6: 0.34804124 | BW6: -0.018941454 | BX6: 0.03647841 | BZ6: -0.15176715 | CA6: 0.34050119 | CB6: 0.047653107 | CC6: -0.084602135 | CD6: 0.22222222 | CE6: -0.3432304 | CF6: 0.18165785 | CJ6: 0.037629918 | CK6: 0.069565217 | CL6: -0.043177893 | CN6: 0.020952381 | CO6: -0.12194706 | CQ6: -0.058823529 | CS6: -0.12839674 | CT6: -0.31518817 | CU6: 0.039660057 | CV6: -0.1170508 | CW6: -0.0098509052 | CX6: 0.0026681913 | CY6: -0.055555556 | CZ6: 0.18830114 | DA6: 0.010635065 | DC6: -0.040707536 | DD6: 0.18746538 | DF6: -0.23255814 | DI6: -0.18726257 | DJ6: -0.0046511628 | DK6: 0.029220779 | DM6: 0.019021739 | DN6: -0.13715047 | DP6: 0.086291995 | DQ6: -0.1 | DR6: 0.28932584 | DS6: -0.062526316 | DY6: -0.099173554 | DZ6: 0.037974684 | EA6: 0.49137931 | EB6: 1.0175439 | EC6: -0.24468085 | ED6: -0.061290323 | EE6: 0.48 | EF6: -0.15269461 | EG6: -0.40417802 | EK6: -0.069364162 | EL6: 0.07518797 | EM6: 0.72774869 | EN6: 0.10837896 | EO6: 0.44947735
A7: 2020 | B7: 8 | C7: 0.069796715 | D7: 0 | E7: 0.14418605 | F7: -0.14285714 | H7: 0.7715736 | J7: 0.017982018 | K7: -0.050808314 | M7: 0.059101655 | P7: 0.49429658 | Q7: -0.16521739 | R7: -0.17619048 | T7: -0.1005996 | V7: -0.066411239 | X7: 0.027758306 | Y7: -0.23741007 | AB7: 0.06034649 | AE7: -0.057177616 | AH7: 0.048780488 | AI7: 0.15591398 | AK7: -0.37278107 | AL7: 0.20785805 | AM7: -0.15050167 | AN7: -0.18708333 | AO7: -0.033033033 | AP7: 0.049438202 | AR7: -0.27906977 | AT7: -0.027027027 | AV7: -0.11479592 | AW7: 0.22979264 | AX7: 0.15106488 | AY7: -0.31345946 | AZ7: 0.18404908 | BA7: -0.040659049 | BB7: 0.17365269 | BC7: 0.21138211 | BE7: -0.0028409091 | BF7: -0.24633803 | BG7: -0.54190296 | BJ7: -0.18069307 | BK7: -0.029304029 | BM7: 0.25729927 | BO7: 0.96721311 | BQ7: -0.13547434 | BR7: -0.14285714 | BS7: -0.080958386 | BT7: -0.25 | BV7: -0.38819211 | BW7: 0.24147806 | BX7: 0.059470549 | BZ7: -0.0049019608 | CA7: -0.12625153 | CB7: -0.12954429 | CC7: -0.0077861482 | CD7: -0.038961039 | CE7: -0.074141049 | CF7: -0.024626866 | CJ7: 0.062687631 | CK7: -0.26317073 | CL7: -0.12725632 | CN7: -0.0018656716 | CO7: 0.11110679 | CQ7: 0.10969388 | CS7: -0.068589244 | CT7: -0.10696762 | CU7: -0.049046322 | CV7: -0.07480313 | CW7: -0.020435601 | CX7: 0.18836723 | CY7: -0.076470588 | CZ7: -0.017932638 | DA7: 0.10523151 | DB7: 0.079862602 | DC7: -0.0093434772 | DD7: 0.60822338 | DF7: -0.18939394 | DI7: -0.01897168 | DJ7: -0.0046728972 | DK7: -0.0094637224 | DM7: 0.14133333 | DN7: -0.12808642 | DP7: 0.082549016 | DQ7: -0.20555556 | DR7: -0.19716776 | DS7: -0.012351224 | DY7: 0.14678899 | DZ7: -0.090785908 | EA7: -0.51445087 | EB7: -0.79069565 | EC7: -0.18913481 | ED7: -0.20687285 | EE7: -0.21081081 | EF7: -0.021201413 | EG7: 0.40091463 | EK7: -0.049689441 | EL7: 0.6451049 | EM7: -0.25151515 | EN7: 0.055510982 | EO7: 0.75456731
A8: 2020 | B8: 9 | C8: -0.037398487 | D8: -0.00021914381 | E8: 0.044715447 | F8: 0.61594203 | H8: -0.32091691 | J8: -0.079980373 | K8: -0.055961071 | M8: -0.10044643 | P8: -0.38231552 | Q8: 0.033958333 | R8: -0.09017341 | T8: -0.17814815 | V8: -0.31053352 | X8: -0.02809985 | Y8: 0.12264151 | AB8: -0.030706317 | AE8: -0.17903226 | AH8: -0.10465116 | AI8: -0.18139535 | AK8: -0.12301887 | AL8: 0.092339979 | AM8: 0.37047244 | AN8: -0.065094823 | AO8: -0.0031055901 | AP8: 0.29122056 | AR8: 0.11827957 | AT8: -0.075277778 | AV8: -0.014409222 | AW8: -0.038885065 | AX8: -0.12478485 | AY8: 0.08652862 | AZ8: 0.012953368 | BA8: 0.029639889 | BB8: 0.0076530612 | BC8: 0.049217002 | BE8: -0.11111111 | BF8: -0.031769763 | BG8: 0.090784044 | BJ8: -0.060422961 | BK8: -0.25660377 | BM8: -0.18867925 | BO8: -0.13333333 | BQ8: -0.10760034 | BR8: -0.087719298 | BS8: 0.40834248 | BT8: 0.34615385 | BV8: -0.27625 | BW8: 0.061016445 | BX8: -0.029529 | BZ8: -0.034482759 | CA8: -0.22659548 | CB8: -0.065490196 | CC8: -0.0024932063 | CD8: -0.047297297 | CE8: -0.0390625 | CF8: -0.14460597 | CJ8: -0.020157279 | CK8: -0.1945272 | CL8: -0.14219235 | CN8: 0.0028037383 | CO8: -0.39499551 | CQ8: -0.12528736 | CS8: -0.15439331 | CT8: -0.14285714 | CU8: -0.252149 | CV8: -0.18446669 | CW8: -0.00027449904 | CX8: -0.038387716 | CY8: 0.2611465 | CZ8: -0.028841595 | DA8: -0.0024483134 | DB8: -0.099403579 | DC8: -0.12218051 | DD8: 0.25815274 | DF8: 0.11214953 | DI8: 0.054372197 | DJ8: 0.0093896714 | DK8: 2.6656051 | DM8: -0.1296729 | DN8: -0.21946903 | DP8: -0.011515739 | DQ8: 0.31468531 | DR8: 0.13568521 | DS8: -0.052296498 | DY8: 0.136 | DZ8: -0.27719821 | EA8: -0.10714286 | EB8: 0.16327378 | EC8: 0 | ED8: -0.28336222 | EE8: 0.082191781 | EF8: -0.054151625 | EG8: -0.1577802 | EK8: 0.08496732 | EL8: 0.26036132 | EM8: -0.1902834 | EN8: 0.032917484 | EO8: -0.22660638
A9: 2020 | B9: 10 | C9: -0.024933396 | D9: 0.00010959592 | E9: 0.49416342 | F9: -0.21973094 | H9: -0.2278481 | J9: 0.0448 | K9: 0.072164948 | M9: -0.096419709 | P9: -0.0030895984 | Q9: -0.53878702 | R9: -0.11435832 | T9: -0.068649542 | V9: 0 | X9: -0.069333333 | Y9: -0.20142857 | AB9: -0.023227534 | AE9: 0.042043222 | AH9: -0.12337662 | AI9: -0.044545455 | AK9: -0.10251721 | AL9: -0.14361191 | AM9: -0.035909221 | AN9: 0.06441886 | AO9: -0.080996885 | AP9: -0.16252073 | AR9: -0.057211538 | AT9: -0.036647642 | AV9: 0.055555556 | AW9: 0.11027569 | AX9: -0.22271386 | AY9: -0.15217391 | AZ9: -0.22506394 | BA9: -0.1937046 | BB9: -0.07721519 | BC9: -0.18550107 | BE9: 0.057692308 | BF9: -0.27793862 | BG9: 0.24337957 | BJ9: -0.13504823 | BK9: -0.15228426 | BL9: 0.14749263 | BM9: -0.14847943 | BO9: 0.057692308 | BQ9: 0.034449761 | BR9: 0.033653846 | BS9: -0.03858145 | BT9: -0.54857143 | BV9: -0.31295337 | BW9: 0.010589803 | BX9: -0.079056739 | BZ9: -0.10204082 | CA9: -0.32990654 | CB9: -0.13501888 | CC9: -0.11863259 | CD9: -0.14893617 | CE9: -0.06097561 | CF9: -0.04293381 | CJ9: -0.0933098 | CK9: -0.16767123 | CL9: -0.045207957 | CN9: 0.0050046598 | CO9: 1.2313874 | CP9: -0.09894624 | CQ9: 0.24835742 | CS9: 0.0034636319 | CT9: -0.17948718 | CU9: -0.030651341 | CV9: -0.055175651 | CW9: -0.093080725 | CX9: -0.13007319 | CY9: -0.58484848 | CZ9: -0.033242243 | DA9: 0.073356968 | DB9: -0.045474614 | DC9: -0.044435496 | DD9: 1.092481 | DF9: -0.058823529 | DI9: -0.17783094 | DJ9: 0.0093023256 | DK9: -0.28670721 | DM9: 0.15704698 | DN9: -0.0090702948 | DP9: -0.069863698 | DQ9: -0.25 | DR9: -0.11469534 | DS9: -0.11900192 | DY9: 0.20422535 | DZ9: 0.17731959 | EA9: -0.17777778 | EB9: -0.071428571 | EC9: -0.20099256 | ED9: -0.15175333 | EE9: -0.2278481 | EF9: -0.038167939 | EG9: -0.042635659 | EK9: -0.036144578 | EL9: -0.20236088 | EM9: 0.025 | EN9: -0.040040544 | EO9: 0.0097431355
A10: 2020 | B10: 11 | C10: 0.10877691 | D10: -0.00010958391 | E10: -0.13020833 | F10: 0.33908046 | H10: 0.16666667 | J10: -0.093415008 | K10: -0.050480769 | M10: 0.15967046 | P10: 0.45867769 | Q10: 0.34185234 | R10: 0.15734099 | T10: -0.32258065 | U10: 0.37873754 | V10: 0.42460317 | X10: 0.093198613 | Y10: -0.069977902 | AB10: 0.067578819 | AD10: 0.96732523 | AE10: 0.10633484 | AH10: 0.48888889 | AI10: 0.3320647 | AK10: 1.5889968 | AL10: 0.037016265 | AM10: 0.34922527 | AN10: 0.11898017 | AO10: 0.0033898305 | AP10: 0.78217822 | AR10: 0.050484447 | AT10: 0.53830163 | AV10: 0.024930748 | AW10: -0.013544018 | AX10: 0.61353574 | AY10: 0.35897436 | AZ10: 0.2310231 | BA10: -0.055055055 | BB10: 0.089163237 | BC10: -0.18324607 | BE10: 0.063636364 | BF10: 0.45682972 | BG10: 0.15922921 | BJ10: -0.37918216 | BK10: 0.02994012 | BL10: 0.11182519 | BM10: 0.20798319 | BO10: 1.0818182 | BQ10: -0.032839963 | BR10: -0.28372093 | BS10: -0.041751115 | BT10: 0.54388186 | BV10: 0.75917547 | BW10: -0.02352533 | BX10: 0.062618388 | BZ10: -0.059659091 | CA10: 0.16317992 | CB10: 0.023286841 | CC10: 0.12229168 | CD10: 0.33333333 | CE10: -0.3961039 | CF10: 0.16074766 | CJ10: 0.068874952 | CK10: 0.020408163 | CL10: 0.034722222 | CN10: 0.0080028191 | CO10: -0.20666782 | CP10: -0.0049554014 | CQ10: 0.84210526 | CS10: 0.14299803 | CT10: 0.265625 | CU10: 0.68379447 | CV10: 0.15606781 | CW10: 0.076899788 | CX10: 0.1585086 | CY10: 0.54501217 | CZ10: 0.1499524 | DA10: 0.087906504 | DB10: 0.27289547 | DC10: 0.10431831 | DD10: 0.44752416 | DF10: 0.23214286 | DI10: 0.14969285 | DJ10: 0.010138249 | DK10: -0.059683313 | DM10: 0.069605568 | DN10: 0.52173913 | DP10: 0.084509744 | DQ10: 0.14184397 | DR10: -0.090418354 | DS10: 0.16013072 | DY10: -0.12280702 | DZ10: 0.58318739 | EA10: 0.1027027 | EB10: 0.11538462 | EC10: -0.052795031 | ED10: 0.21168924 | EE10: 0.098360656 | EF10: 0.20634921 | EG10: 0.23481781 | EK10: 0.0625 | EL10: -0.078224101 | EM10: 0.46829268 | EN10: 0.011542146 | EO10: 0.77192982
A11: 2020 | B11: 12 | C11: 0.037065957 | D11: 3.5711031e-05 | E11: 0.93712575 | F11: -0.27038627 | H11: 0.14519906 | J11: 0.13231982 | K11: 0.15696203 | M11: -0.01759134 | P11: -0.24220963 | Q11: 0.18834446 | R11: 2.5095041 | T11: -0.14857143 | U11: 0.37550201 | V11: -0.069637883 | W11: 0.25390156 | X11: 0.12387916 | Y11: -0.32337633 | AB11: 0.0019235528 | AD11: 0.1208961 | AE11: 0.03135651 | AH11: 0.36318408 | AI11: -0.20535714 | AK11: -0.37037037 | AL11: 0.083288264 | AM11: 0.15547703 | AN11: 0.026006904 | AO11: -0.0033783784 | AP11: -0.17444444 | AR11: -0.0097087379 | AT11: -0.094594595 | AV11: 0.11891892 | AW11: 0.0026152337 | AX11: -0.13563309 | AY11: -0.06918239 | AZ11: -0.09919571 | BA11: -0.081920904 | BB11: 0.023929471 | BC11: -0.17307692 | BE11: 0.72649573 | BF11: 0.20733945 | BG11: 0.024496938 | BJ11: 0.31137725 | BK11: 0.37790698 | BL11: -0.16416185 | BM11: 0.19304348 | BO11: -0.31877729 | BQ11: 0.18507891 | BR11: 0.053571429 | BS11: 0.34517766 | BT11: 0.35146215 | BV11: 1.3292369 | BW11: 0.17297989 | BX11: 0.087780205 | BZ11: 0.48942598 | CA11: 0.19568345 | CB11: 0.17873652 | CC11: 0.1592175 | CD11: -0.15 | CE11: 0.05734767 | CF11: -0.082125604 | CJ11: 0.02577325 | CK11: 0.12419355 | CL11: 0.037217816 | CN11: 1.2447102 | CO11: 0.40056831 | CP11: 0.16533865 | CQ11: 0.18285714 | CS11: 0.23252804 | CT11: 0.022222222 | CU11: -0.0046948357 | CV11: 0.028056124 | CW11: -0.019679505 | CX11: -0.01237828 | CY11: 0.038582677 | CZ11: -0.039152496 | DA11: -0.2241943 | DB11: -0.1744186 | DC11: -0.072585844 | DD11: -0.12404449 | DF11: -0.13768116 | DI11: -0.098143982 | DJ11: -0.20209854 | DK11: -0.11658031 | DM11: -0.42624729 | DN11: 0.15037594 | DP11: 0.049060875 | DQ11: 0.071428571 | DR11: 0.077151335 | DS11: 0.18122066 | DU11: 0.70997104 | DY11: -0.17333333 | DZ11: -0.086283186 | EA11: -0.024509804 | EB11: 0.6062069 | EC11: -0.20655738 | ED11: -0.35490196 | EE11: -0.097014925 | EF11: 1.8453947 | EG11: 0.2579235 | EK11: -0.070588235 | EL11: 0.12844037 | EM11: -0.019933555 | EN11: 0.031924199 | EO11: -0.30693069
A12: 2021 | B12: 1 | C12: -0.010190496 | D12: 0 | E12: 2.2071097 | F12: 0.26470588 | H12: 0.84253579 | J12: -0.095972153 | K12: 0.052516411 | M12: -0.017217631 | P12: -0.011214953 | Q12: 0.31178082 | R12: -0.11173908 | T12: 0.76314318 | U12: -0.37751825 | V12: 0.092814371 | W12: 0.74724749 | X12: -0.16423223 | Y12: 0.19397993 | AB12: -0.0096722765 | AD12: 0.05616816 | AE12: 0.23595506 | AH12: 0.14233577 | AI12: -0.033707865 | AK12: 0.26470588 | AL12: 0.20519221 | AM12: 0.080275229 | AN12: 0.59376402 | AO12: 0.074576271 | AP12: 0.17765814 | AR12: 0.19607843 | AT12: 0.68656716 | AV12: -0.0048309179 | AW12: -0.053472449 | AX12: -0.40952381 | AY12: 1.5 | AZ12: 1.0119048 | BA12: 0.21115385 | BB12: 0.097170972 | BC12: 0 | BE12: -0.0082508251 | BF12: 0.70212766 | BG12: -0.055508113 | BJ12: -0.059360731 | BK12: -0.10970464 | BL12: -0.00802213 | BM12: 0.31195335 | BO12: 0.019230769 | BQ12: -0.030669895 | BR12: 0.798151 | BS12: 0.011006289 | BT12: 0.42568251 | BV12: 2.4601227 | BW12: -0.057861254 | BX12: 0.036535806 | BZ12: 0.27991886 | CA12: -0.38093328 | CB12: 0.86375063 | CC12: 0.2317583 | CD12: 0.30147059 | CE12: -0.071186441 | CF12: -0.072807018 | CJ12: -0.057824221 | CK12: 0.276901 | CL12: 0.15882353 | CN12: 1.407377 | CO12: 0.2 | CP12: -0.12393162 | CQ12: -0.12318841 | CS12: 0.36226811 | CT12: -0.038647343 | CU12: 0.71226415 | CV12: 0.067973621 | CW12: 0.14711787 | CX12: 0.10427807 | CY12: -0.044730857 | CZ12: -0.014116417 | DA12: 0.1589404 | DB12: 0.08318662 | DC12: -0.045169715 | DD12: 0.102397 | DF12: 0.18487395 | DI12: 0.019020892 | DJ12: -0.071469411 | DK12: 1.9061584 | DM12: 0.19848771 | DN12: -0.023529412 | DP12: -0.11142019 | DQ12: 0.031884058 | DR12: 0.12672176 | DS12: 0.16812401 | DU12: -0.087829664 | DY12: 0.77419355 | DZ12: 1.1912833 | EA12: 0.32663317 | EB12: 0.43838557 | EC12: 0.23140496 | ED12: -0.039513678 | EE12: 0.36363636 | EF12: 0.019653179 | EG12: 0.020851434 | EI12: -0.093385924 | EK12: 0.25316456 | EL12: 0.032520325 | EM12: 0.18644068 | EN12: -0.066542347 | EO12: -0.46160714
A13: 2021 | B13: 2 | C13: 0.02780559 | D13: -0.00010959201 | E13: 0.07373494 | F13: 0.16744186 | H13: -0.061043285 | J13: -0.035753575 | K13: 0.12058212 | M13: 0.019621584 | P13: -0.1342155 | Q13: 0.92147034 | R13: 0.037910923 | T13: 0.35289453 | U13: 0.034709193 | V13: 0.10136986 | W13: 0.032328767 | X13: -0.010721104 | Y13: 0.074229692 | AB13: -0.0016287353 | AD13: -0.34486134 | AE13: -0.018716578 | AH13: 0.057507987 | AI13: 0.52906977 | AK13: -0.087209302 | AL13: -0.022783761 | AM13: -0.11004954 | AN13: 0.24883885 | AO13: 0.072555205 | AP13: 0.71428571 | AR13: 0.66393443 | AT13: -0.17256637 | AV13: 0.077669903 | AW13: 0.13193248 | AX13: -0.033026114 | AY13: -0.075675676 | AZ13: 0.79142012 | BA13: -0.13020006 | BB13: -0.1132287 | BC13: 0.14341085 | BE13: -0.013311148 | BF13: -0.034821429 | BG13: 0.14014467 | BJ13: -0.087378641 | BK13: 0.11374408 | BL13: -0.010875627 | BM13: -0.14777778 | BO13: 0.10691824 | BQ13: -0.048293089 | BR13: -0.090831191 | BS13: 0.10202177 | BT13: 0.16312057 | BV13: -0.25531915 | BW13: 0.080643087 | BX13: -0.022566288 | BZ13: -0.12202853 | CA13: 0.29157667 | CB13: -0.20032371 | CC13: -0.010676379 | CD13: -0.10169492 | CE13: 0.02189781 | CF13: 0.4115421 | CJ13: -0.057739027 | CK13: 0.26966292 | CL13: 0.15177665 | CN13: -0.34439905 | CO13: 0.72222006 | CP13: -0.021463415 | CQ13: 0.01046832 | CS13: 0.024665982 | CT13: -0.025125628 | CU13: 0.22727273 | CV13: 0.040018047 | CW13: 0.04275 | CX13: 0.11228814 | CY13: 0.81269841 | CZ13: -0.067130054 | DA13: 0.14415584 | DB13: 0.34457538 | DC13: -0.054800643 | DD13: -0.24308621 | DE13: -0.0089285714 | DF13: 0.092198582 | DI13: 0.020195838 | DJ13: 0.13423645 | DK13: 1.4510595 | DM13: 0.16403785 | DN13: 0.041499331 | DP13: -0.021666951 | DQ13: 0.0056179775 | DR13: -0.015892421 | DS13: -0.08574345 | DU13: -0.038461538 | DY13: -0.14545455 | DZ13: 0.34585635 | EA13: 0.26136364 | EB13: 0.86567164 | EC13: -0.053691275 | ED13: 0.047468354 | EE13: -0.078787879 | EF13: 0.56689342 | EG13: 0.16680851 | EI13: -0.12595841 | EK13: -0.058080808 | EL13: 0.072834646 | EM13: 0.068571429 | EN13: 0.0064180878 | EO13: 0.5721393
A14: 2021 | B14: 3 | C14: 0.045404985 | D14: -0.00010837252 | E14: 0.13105925 | F14: -0.035856574 | H14: -0.0047281324 | J14: 0.045065602 | K14: 0.24860853 | M14: 0.2419244 | P14: 0.13537118 | Q14: -0.11413043 | R14: -0.15581098 | T14: -0.19988277 | U14: -0.16591115 | V14: 0.12437811 | W14: -0.18059979 | X14: -0.15944181 | Y14: -0.0091264668 | AB14: 0.037340338 | AD14: -0.72360558 | AE14: 0.18310627 | AH14: -0.25377644 | AI14: -0.091254753 | AK14: -0.11464968 | AL14: 0.0046629928 | AM14: -0.054075547 | AN14: -0.053307788 | AO14: -0.10882353 | AP14: -0.334 | AR14: -0.12315271 | AT14: -0.096256684 | AV14: -0.10810811 | AW14: -0.10377358 | AX14: -0.32962669 | AY14: -0.10233918 | AZ14: 0.072667217 | BA14: 0.024096386 | BB14: -0.074589128 | BC14: -0.37966102 | BE14: -0.13827993 | BF14: -0.06012951 | BG14: -0.065820777 | BJ14: -0.021276596 | BK14: -0.16170213 | BL14: -0.068508599 | BM14: -0.11994785 | BO14: 0.017045455 | BQ14: 0.045494313 | BR14: -0.45240339 | BS14: -0.042337003 | BT14: -0.1402439 | BV14: -0.14285714 | BW14: -0.021840038 | BX14: 0.037170256 | BZ14: -0.10108303 | CA14: -0.06187291 | CB14: 0.028538659 | CC14: -0.088193811 | CD14: -0.050314465 | CE14: -0.039285714 | CF14: -0.22319035 | CJ14: 0.070803077 | CK14: -0.19469027 | CL14: -0.11855443 | CN14: -0.080238899 | CO14: -0.27258092 | CP14: 0.041874377 | CQ14: -0.10523446 | CS14: -0.10732197 | CT14: -0.048969072 | CU14: 0.14029181 | CV14: 0.13732889 | CW14: 0.056820906 | CX14: -0.046394558 | CY14: -0.045534151 | CZ14: 0.081814411 | DA14: -0.14733258 | DB14: 0.18857661 | DC14: 0.0085458953 | DD14: -0.03458792 | DE14: 0.12012012 | DF14: -0.13636364 | DI14: 0.056088782 | DJ14: -0.37676439 | DK14: -0.074722108 | DM14: -0.098915989 | DN14: 0.020565553 | DP14: 0.028488316 | DQ14: -0.072625698 | DR14: -0.077018634 | DS14: -0.025679196 | DU14: -0.11089655 | DY14: -0.095744681 | DZ14: -0.066912972 | EA14: -0.033033033 | EB14: -0.20088 | EC14: -0.039007092 | ED14: -0.099697885 | EE14: -0.11842105 | EF14: -0.22033285 | EG14: 0.10503282 | EI14: -0.059254084 | EK14: -0.082439678 | EL14: -0.17247706 | EM14: 0.10695187 | EN14: 0.014429012 | EO14: -0.029535865
A15: 2021 | B15: 4 | C15: 0.052910546 | D15: 0 | E15: -0.053571429 | F15: -0.090909091 | H15: -0.17814727 | J15: -0.050218341 | K15: -0.18127786 | M15: -0.079136691 | P15: -0.21730769 | Q15: -0.19018405 | R15: 0.042965204 | T15: -0.19399267 | U15: 0.069565217 | V15: -0.17035398 | W15: -0.59983806 | X15: 0.067820558 | Y15: -0.12894737 | AB15: -0.011247681 | AD15: -0.14594595 | AE15: -0.40350069 | AH15: 0.24291498 | AI15: -0.16317992 | AK15: -0.15107914 | AL15: -0.05907173 | AM15: -0.042034468 | AN15: -0.083333333 | AO15: -0.11881188 | AP15: -0.13513514 | AR15: 0.23595506 | AT15: -0.10650888 | AV15: -0.04040404 | AW15: 0.076740238 | AX15: -0.12322275 | AY15: -0.2247557 | AZ15: -0.2986913 | BA15: -0.039215686 | BB15: 0.18579235 | BC15: -0.1147541 | BE15: 0.035225049 | BF15: 0.052165354 | BG15: -0.044991511 | BJ15: -0.059782609 | BK15: -0.23350254 | BL15: -0.11319613 | BM15: 0.1362963 | BO15: -0.10614525 | BQ15: -0.041841004 | BR15: -0.12392427 | BS15: 0.014736222 | BT15: -0.12765957 | BV15: -0.16111111 | BW15: 0.00018251506 | BX15: -0.0098573808 | BZ15: -0.15060241 | CA15: -0.098039216 | CB15: -0.043030502 | CC15: -0.021678322 | CD15: -0.066225166 | CE15: 0.055762082 | CF15: -0.13114754 | CJ15: -0.033597081 | CK15: -0.10043956 | CL15: -0.0195 | CN15: 0.092603049 | CO15: -0.20177253 | CP15: 0.070813397 | CQ15: 0.12004875 | CS15: -0.0078651685 | CT15: -0.032520325 | CU15: 0.049212598 | CV15: 0.004917189 | CW15: -0.011796733 | CX15: -0.09858753 | CY15: -0.24954128 | CZ15: 0.06679622 | DA15: 0.025559105 | DB15: -0.1482329 | DC15: 0.028663279 | DD15: -0.2792511 | DE15: -0.13672922 | DF15: -0.28571429 | DI15: 0.095143425 | DJ15: 0.0052264808 | DK15: 0.041156841 | DM15: -0.027067669 | DN15: -0.047858942 | DP15: 0.10306596 | DQ15: -0.060240964 | DR15: 0.043068641 | DS15: 0.1631016 | DU15: -0.04685076 | DW15: 0 | DY15: -0.23529412 | DZ15: -0.19313682 | EA15: -0.33229814 | EB15: -0.27970768 | EC15: -0.15498155 | ED15: -0.15436242 | EE15: -0.097014925 | EF15: -0.17958237 | EG15: -0.12871287 | EH15: -0.15711253 | EI15: -0.047965435 | EK15: -0.27830533 | EL15: -0.15077605 | EM15: -0.070048309 | EN15: 0.10037054 | EO15: 0.057608696
A16: 2021 | B16: 5 | C16: 0.0065660538 | D16: -0.0001096159 | E16: -0.067505241 | F16: 0.12272727 | H16: -0.0043352601 | J16: 0.087356322 | K16: 0.02722323 | M16: 0.032151442 | P16: -0.088452088 | Q16: -0.060606061 | R16: 0.055120395 | T16: -0.17742229 | U16: 0.013211382 | V16: 0.025333333 | W16: -0.17361392 | X16: 0.0041349653 | Y16: -0.2326284 | AB16: 0.052868541 | AD16: -0.16033755 | AE16: 0.049420849 | AH16: -0.16449511 | AI16: -0.075 | AK16: -0.042372881 | AL16: 0.071300448 | AM16: -0.052215884 | AN16: -0.23376623 | AO16: 0.10486891 | AP16: -0.16319444 | AR16: 0.036363636 | AT16: -0.15231788 | AV16: -0.13157895 | AW16: 0.13465784 | AX16: -0.017567568 | AY16: -0.06302521 | AZ16: 0.18770582 | BA16: -0.26122449 | BB16: -0.18663594 | BC16: -0.24074074 | BD16: 0.0080307263 | BE16: -0.096408318 | BF16: -0.080449018 | BG16: -0.20622222 | BJ16: -0.01734104 | BK16: -0.039735099 | BL16: 0.090784983 | BM16: 0.19947849 | BO16: -0.1125 | BP16: -0.26440539 | BQ16: 0.17467249 | BR16: -0.10805501 | BS16: 0.1446413 | BT16: 0.17886179 | BV16: 0.059602649 | BW16: 0.083515815 | BX16: 0.046531127 | BZ16: 0.037825059 | CA16: 0.20158103 | CB16: -0.19322777 | CC16: 0.097614088 | CD16: -0.13475177 | CE16: 0.059859155 | CF16: -0.28699106 | CJ16: 0.018656876 | CK16: -0.13681896 | CL16: -0.078531362 | CN16: -0.43152455 | CO16: 0 | CP16: 0.27077748 | CQ16: -0.2078346 | CS16: -0.1398641 | CT16: -0.10644258 | CU16: 0.080675422 | CV16: 0.14967486 | CW16: 0.14485767 | CX16: -0.039727762 | CY16: -0.24816626 | CZ16: 0.012041959 | DA16: -0.082294912 | DB16: -0.10268657 | DC16: 0.1083359 | DD16: -0.054262074 | DE16: -0.059006211 | DF16: -0.020526316 | DI16: -0.10295643 | DJ16: -0.13344887 | DK16: 0.15213675 | DL16: -0.0040241449 | DM16: -0.1251932 | DN16: 0.26719577 | DP16: -0.016735043 | DQ16: 0.038461538 | DR16: -0.014193548 | DS16: -0.019704433 | DU16: 0.084635417 | DW16: -0.22227273 | DY16: 0.069230769 | DZ16: -0.091057797 | EA16: 0.01627907 | EB16: -0.38012509 | EC16: -0.069868996 | ED16: -0.031746032 | EE16: 0 | EF16: -0.0011312217 | EG16: -0.1469697 | EH16: 0.085642317 | EI16: 0.15410661 | EK16: -0.20040486 | EL16: -0.18537859 | EM16: -0.21298701 | EN16: 0.021094728 | EO16: 0.052415211
